wandb: Currently logged in as: hadars (autoconvnext). Use `wandb login --relogin` to force relogin
wandb: wandb version 0.13.5 is available!  To upgrade, please run:
wandb:  $ pip install wandb --upgrade
wandb: Tracking run with wandb version 0.13.4
wandb: Run data is saved locally in /home/s3092593/benchmarking_rl/wandb/run-20221201_094617-pqm0m5v2
wandb: Run `wandb offline` to turn off syncing.
wandb: Syncing run rich-shape-1
wandb: ⭐️ View project at https://wandb.ai/autoconvnext/benchmark_final_impala_large_4_DQN_modern_Phoenix_model_50000000_0_impala_large_4
wandb: 🚀 View run at https://wandb.ai/autoconvnext/benchmark_final_impala_large_4_DQN_modern_Phoenix_model_50000000_0_impala_large_4/runs/pqm0m5v2
wandb: Waiting for W&B process to finish... (success).
wandb: 
wandb: Run history:
wandb: loss █▁▂▂▂▂▂▂▂▃▃▃▃▃▄▄▄▄▄▃▃▃▃▃▃▃▃▁▂▁
wandb:  mae █▅▄▄▃▃▃▂▂▂▂▂▂▂▁▁▁▁▁▁▁▁▁▁▁▁▁▁▁▁
wandb: 
wandb: Run summary:
wandb: loss 0.92746
wandb:  mae 0.8833
wandb: 
wandb: Synced rich-shape-1: https://wandb.ai/autoconvnext/benchmark_final_impala_large_4_DQN_modern_Phoenix_model_50000000_0_impala_large_4/runs/pqm0m5v2
wandb: Synced 6 W&B file(s), 0 media file(s), 1 artifact file(s) and 0 other file(s)
wandb: Find logs at: ./wandb/run-20221201_094617-pqm0m5v2/logs
Traceback (most recent call last):
  File "/data1/s3092593/rlenv/lib/python3.8/site-packages/wandb/sdk/wandb_init.py", line 1075, in init
    wi.setup(kwargs)
  File "/data1/s3092593/rlenv/lib/python3.8/site-packages/wandb/sdk/wandb_init.py", line 302, in setup
    self._log_setup(settings)
  File "/data1/s3092593/rlenv/lib/python3.8/site-packages/wandb/sdk/wandb_init.py", line 446, in _log_setup
    filesystem._safe_makedirs(os.path.dirname(settings.log_user))
  File "/data1/s3092593/rlenv/lib/python3.8/site-packages/wandb/sdk/lib/filesystem.py", line 10, in _safe_makedirs
    os.makedirs(dir_name)
  File "/data1/s3092593/rlenv/lib/python3.8/os.py", line 213, in makedirs
    makedirs(head, exist_ok=exist_ok)
  File "/data1/s3092593/rlenv/lib/python3.8/os.py", line 223, in makedirs
    mkdir(name, mode)
OSError: [Errno 122] Disk quota exceeded: '/home/s3092593/benchmarking_rl/wandb/run-20221201_114852-e3g3g1fr'
error
Traceback (most recent call last):
  File "/data1/s3092593/rlenv/lib/python3.8/site-packages/wandb/sdk/wandb_init.py", line 1075, in init
    wi.setup(kwargs)
  File "/data1/s3092593/rlenv/lib/python3.8/site-packages/wandb/sdk/wandb_init.py", line 302, in setup
    self._log_setup(settings)
  File "/data1/s3092593/rlenv/lib/python3.8/site-packages/wandb/sdk/wandb_init.py", line 446, in _log_setup
    filesystem._safe_makedirs(os.path.dirname(settings.log_user))
  File "/data1/s3092593/rlenv/lib/python3.8/site-packages/wandb/sdk/lib/filesystem.py", line 10, in _safe_makedirs
    os.makedirs(dir_name)
  File "/data1/s3092593/rlenv/lib/python3.8/os.py", line 213, in makedirs
    makedirs(head, exist_ok=exist_ok)
  File "/data1/s3092593/rlenv/lib/python3.8/os.py", line 223, in makedirs
    mkdir(name, mode)
OSError: [Errno 122] Disk quota exceeded: '/home/s3092593/benchmarking_rl/wandb/run-20221201_114852-e3g3g1fr'
--- Logging error ---
Traceback (most recent call last):
  File "/data1/s3092593/rlenv/lib/python3.8/logging/__init__.py", line 1089, in emit
    self.flush()
  File "/data1/s3092593/rlenv/lib/python3.8/logging/__init__.py", line 1069, in flush
    self.stream.flush()
OSError: [Errno 122] Disk quota exceeded
Call stack:
  File "/data1/s3092593/rlenv/lib/python3.8/threading.py", line 890, in _bootstrap
    self._bootstrap_inner()
  File "/data1/s3092593/rlenv/lib/python3.8/threading.py", line 932, in _bootstrap_inner
    self.run()
  File "/data1/s3092593/rlenv/lib/python3.8/site-packages/wandb/sdk/internal/internal_util.py", line 50, in run
    self._run()
  File "/data1/s3092593/rlenv/lib/python3.8/site-packages/wandb/sdk/internal/internal_util.py", line 101, in _run
    self._process(record)
  File "/data1/s3092593/rlenv/lib/python3.8/s