wandb: Currently logged in as: hadars (autoconvnext). Use `wandb login --relogin` to force relogin
wandb: wandb version 0.13.5 is available!  To upgrade, please run:
wandb:  $ pip install wandb --upgrade
wandb: Tracking run with wandb version 0.13.4
wandb: Run data is saved locally in /home/s3092593/benchmarking_rl/wandb/run-20221201_090912-nfiglqs7
wandb: Run `wandb offline` to turn off syncing.
wandb: Syncing run worldly-sun-1
wandb: ⭐️ View project at https://wandb.ai/autoconvnext/benchmark_final_impala_large_1_DQN_modern_Phoenix_model_50000000_0_impala_large_1
wandb: 🚀 View run at https://wandb.ai/autoconvnext/benchmark_final_impala_large_1_DQN_modern_Phoenix_model_50000000_0_impala_large_1/runs/nfiglqs7
wandb: Waiting for W&B process to finish... (success).
wandb: 
wandb: Run history:
wandb: loss ▁▅▅▆▆▆▆▇▇▆▇█▇███▇█▆▆▇▅▅▆▆▆▅▅▅▆
wandb:  mae █▅▄▃▃▃▂▂▂▂▂▂▁▁▁▁▁▁▁▁▁▁▁▁▁▁▁▁▁▁
wandb: 
wandb: Run summary:
wandb: loss 0.97811
wandb:  mae 0.89343
wandb: 
wandb: Synced worldly-sun-1: https://wandb.ai/autoconvnext/benchmark_final_impala_large_1_DQN_modern_Phoenix_model_50000000_0_impala_large_1/runs/nfiglqs7
wandb: Synced 6 W&B file(s), 0 media file(s), 1 artifact file(s) and 0 other file(s)
wandb: Find logs at: ./wandb/run-20221201_090912-nfiglqs7/logs
wandb: wandb version 0.13.5 is available!  To upgrade, please run:
wandb:  $ pip install wandb --upgrade
wandb: Tracking run with wandb version 0.13.4
wandb: Run data is saved locally in /home/s3092593/benchmarking_rl/wandb/run-20221201_102027-1b7lov9d
wandb: Run `wandb offline` to turn off syncing.
wandb: Syncing run solar-silence-2
wandb: ⭐️ View project at https://wandb.ai/autoconvnext/benchmark_final_impala_large_1_DQN_modern_Phoenix_model_50000000_0_impala_large_1
wandb: 🚀 View run at https://wandb.ai/autoconvnext/benchmark_final_impala_large_1_DQN_modern_Phoenix_model_50000000_0_impala_large_1/runs/1b7lov9d
wandb: Waiting for W&B process to finish... (success).
wandb: 
wandb: Run history:
wandb: loss ▁▄▄▄▁▃▄▁▃▄▄▅▆▅▆█▅▄▄▆▅▅▃▅▅▃▂▃▂▃
wandb:  mae █▄▃▃▂▂▂▂▂▁▁▁▁▁▁▁▁▁▁▁▁▁▁▁▁▁▁▁▁▁
wandb: 
wandb: Run summary:
wandb: loss 0.95658
wandb:  mae 0.91025
wandb: 
wandb: Synced solar-silence-2: https://wandb.ai/autoconvnext/benchmark_final_impala_large_1_DQN_modern_Phoenix_model_50000000_0_impala_large_1/runs/1b7lov9d
wandb: Synced 6 W&B file(s), 0 media file(s), 1 artifact file(s) and 0 other file(s)
wandb: Find logs at: ./wandb/run-20221201_102027-1b7lov9d/logs
Traceback (most recent call last):
  File "/data1/s3092593/rlenv/lib/python3.8/site-packages/wandb/sdk/wandb_init.py", line 1075, in init
    wi.setup(kwargs)
  File "/data1/s3092593/rlenv/lib/python3.8/site-packages/wandb/sdk/wandb_init.py", line 302, in setup
    self._log_setup(settings)
  File "/data1/s3092593/rlenv/lib/python3.8/site-packages/wandb/sdk/wandb_init.py", line 446, in _log_setup
    filesystem._safe_makedirs(os.path.dirname(settings.log_user))
  File "/data1/s3092593/rlenv/lib/python3.8/site-packages/wandb/sdk/lib/filesystem.py", line 10, in _safe_makedirs
    os.makedirs(dir_name)
  File "/data1/s3092593/rlenv/lib/python3.8/os.py", line 213, in makedirs
    makedirs(head, exist_ok=exist_ok)
  File "/data1/s3092593/rlenv/lib/python3.8/os.py", line 223, in makedirs
    mkdir(name, mode)
OSError: [Errno 122] Disk quota exceeded: '/home/s3092593/benchmarking_rl/wandb/run-20221201_113335-2evnny94'
error
Traceback (most recent call last):
  File "/data1/s3092593/rlenv/lib/python3.8/site-packages/wandb/sdk/wandb_init.py", line 1075, in init
    wi.setup(kwargs)
  File "/data1/s3092593/rlenv/lib/python3.8/site-packages/wandb/sdk/wandb_init.py", line 302, in setup
    self._log_setup(settings)
  File "/data1/s3092593/rlenv/lib/python3.8/site-packages/wandb/sdk/wandb_init.py", line 446, in _log_setup
    filesystem._safe_makedirs(os.path.dirname(settings.log_user))
  File "/data1/s3092593/rlenv/lib/python3.8/site-packages/wandb/sdk/lib/filesystem.py", line 10, in _safe_makedirs
    os.makedirs(dir_name)
  File "/data1/s3092593/rlenv/lib/python3.8/os.py", line 213, in makedirs
    makedirs(head, exist_ok=exist_ok)
  File "/data1/s3092593/rlenv/lib/python3.8/os.py", line 223, in makedirs
    mkdir(name, mode)
OSError: [Errno 122] Disk quota exceeded: '/home/s3092593/benchmarking_rl/wandb/run-20221201_113335-2evnny94'
wandb: ERROR Abnormal program exit
Traceback (most recent call last):
  File "/data1/s3092593/rlenv/lib/python3.8/site-packages/wandb/sdk/wandb_init.py", line 1075, in init
    wi.setup(kwargs)
  File "/data1/s3092593/rlenv/lib/python3.8/site-packages/wandb/sdk/wandb_init.py", line 302, in setup
    self._log_setup(settings)
  File "/data1/s3092593/rlenv/lib/python3.8/site-packages/wandb/sdk/wandb_init.py", line 446, in _log_setup
    filesystem._safe_makedirs(os.path.dirname(settings.log_user))
  File "/data1/s3092593/rlenv/lib/python3.8/site-packages/wandb/sdk/lib/filesystem.py", line 10, in _safe_makedirs
    os.makedirs(dir_name)
  File "/data1/s3092593/rlenv/lib/python3.8/os.py", line 213, in makedirs
    makedirs(head, exist_ok=exist_ok)
  File "/data1/s3092593/rlenv/lib/python3.8/os.py", line 223, in makedirs
    mkdir(name, mode)
OSError: [Errno 122] Disk quota exceeded: '/home/s3092593/benchmarking_rl/wandb/run-20221201_113335-2evnny94'

The above exception was the direct cause of the following exception:

Traceback (most recent call last):
  File "train.py", line 106, in <module>
    main(args, train_dataset, test_dataset)
  File "train.py", line 40, in main
    wandb.init(project=f'benchmark_{proj_name}_{mname}', config=args)
  File "/data1/s3092593/rlenv/lib/python3.8/site-packages/wandb/sdk/wandb_init.py", line 1116, in init
    raise Exception("problem") from error_seen
Exception: problem
