Traceback (most recent call last):
  File "/data1/s3092593/rlenv/lib/python3.8/site-packages/wandb/sdk/wandb_init.py", line 1075, in init
    wi.setup(kwargs)
  File "/data1/s3092593/rlenv/lib/python3.8/site-packages/wandb/sdk/wandb_init.py", line 165, in setup
    self._wl = wandb_setup.setup()
  File "/data1/s3092593/rlenv/lib/python3.8/site-packages/wandb/sdk/wandb_setup.py", line 312, in setup
    ret = _setup(settings=settings)
  File "/data1/s3092593/rlenv/lib/python3.8/site-packages/wandb/sdk/wandb_setup.py", line 307, in _setup
    wl = _WandbSetup(settings=settings)
  File "/data1/s3092593/rlenv/lib/python3.8/site-packages/wandb/sdk/wandb_setup.py", line 293, in __init__
    _WandbSetup._instance = _WandbSetup__WandbSetup(settings=settings, pid=pid)
  File "/data1/s3092593/rlenv/lib/python3.8/site-packages/wandb/sdk/wandb_setup.py", line 106, in __init__
    self._setup()
  File "/data1/s3092593/rlenv/lib/python3.8/site-packages/wandb/sdk/wandb_setup.py", line 234, in _setup
    self._setup_manager()
  File "/data1/s3092593/rlenv/lib/python3.8/site-packages/wandb/sdk/wandb_setup.py", line 265, in _setup_manager
    self._manager = wandb_manager._Manager(
  File "/data1/s3092593/rlenv/lib/python3.8/site-packages/wandb/sdk/wandb_manager.py", line 108, in __init__
    self._service.start()
  File "/data1/s3092593/rlenv/lib/python3.8/site-packages/wandb/sdk/service/service.py", line 112, in start
    self._launch_server()
  File "/data1/s3092593/rlenv/lib/python3.8/site-packages/wandb/sdk/service/service.py", line 108, in _launch_server
    assert ports_found
AssertionError
wandb: ERROR Abnormal program exit
Traceback (most recent call last):
  File "/data1/s3092593/rlenv/lib/python3.8/site-packages/wandb/sdk/wandb_init.py", line 1075, in init
    wi.setup(kwargs)
  File "/data1/s3092593/rlenv/lib/python3.8/site-packages/wandb/sdk/wandb_init.py", line 165, in setup
    self._wl = wandb_setup.setup()
  File "/data1/s3092593/rlenv/lib/python3.8/site-packages/wandb/sdk/wandb_setup.py", line 312, in setup
    ret = _setup(settings=settings)
  File "/data1/s3092593/rlenv/lib/python3.8/site-packages/wandb/sdk/wandb_setup.py", line 307, in _setup
    wl = _WandbSetup(settings=settings)
  File "/data1/s3092593/rlenv/lib/python3.8/site-packages/wandb/sdk/wandb_setup.py", line 293, in __init__
    _WandbSetup._instance = _WandbSetup__WandbSetup(settings=settings, pid=pid)
  File "/data1/s3092593/rlenv/lib/python3.8/site-packages/wandb/sdk/wandb_setup.py", line 106, in __init__
    self._setup()
  File "/data1/s3092593/rlenv/lib/python3.8/site-packages/wandb/sdk/wandb_setup.py", line 234, in _setup
    self._setup_manager()
  File "/data1/s3092593/rlenv/lib/python3.8/site-packages/wandb/sdk/wandb_setup.py", line 265, in _setup_manager
    self._manager = wandb_manager._Manager(
  File "/data1/s3092593/rlenv/lib/python3.8/site-packages/wandb/sdk/wandb_manager.py", line 108, in __init__
    self._service.start()
  File "/data1/s3092593/rlenv/lib/python3.8/site-packages/wandb/sdk/service/service.py", line 112, in start
    self._launch_server()
  File "/data1/s3092593/rlenv/lib/python3.8/site-packages/wandb/sdk/service/service.py", line 108, in _launch_server
    assert ports_found
AssertionError

The above exception was the direct cause of the following exception:

Traceback (most recent call last):
  File "train.py", line 106, in <module>
    main(args, train_dataset, test_dataset)
  File "train.py", line 40, in main
    wandb.init(project=f'benchmark_{proj_name}_{mname}', config=args)
  File "/data1/s3092593/rlenv/lib/python3.8/site-packages/wandb/sdk/wandb_init.py", line 1116, in init
    raise Exception("problem") from error_seen
Exception: problem
